2024-02-10 23:05:54.148 | ERROR    | handlers.custom_handlers.popular:callback_serial_handler:25 - An error has been caught in function 'callback_serial_handler', process 'MainProcess' (31508), thread 'WorkerThread2' (6195621888):
Traceback (most recent call last):

  File "/Library/Frameworks/Python.framework/Versions/3.11/lib/python3.11/threading.py", line 995, in _bootstrap
    self._bootstrap_inner()
    │    └ <function Thread._bootstrap_inner at 0x100c87ce0>
    └ <WorkerThread(WorkerThread2, started daemon 6195621888)>
  File "/Library/Frameworks/Python.framework/Versions/3.11/lib/python3.11/threading.py", line 1038, in _bootstrap_inner
    self.run()
    │    └ <function WorkerThread.run at 0x100e79440>
    └ <WorkerThread(WorkerThread2, started daemon 6195621888)>
  File "/Library/Frameworks/Python.framework/Versions/3.11/lib/python3.11/site-packages/telebot/util.py", line 90, in run
    task(*args, **kwargs)
    │     │       └ {'handlers': [{'function': <function bot_popular at 0x103086200>, 'pass_bot': False, 'filters': {'func': <function <lambda> a...
    │     └ (<telebot.types.CallbackQuery object at 0x1030cc390>,)
    └ <bound method TeleBot._run_middlewares_and_handler of <telebot.TeleBot object at 0x100ab6bd0>>
  File "/Library/Frameworks/Python.framework/Versions/3.11/lib/python3.11/site-packages/telebot/__init__.py", line 6720, in _run_middlewares_and_handler
    result = handler['function'](message)
             │                   └ <telebot.types.CallbackQuery object at 0x1030cc390>
             └ {'function': <function callback_serial_handler at 0x103086480>, 'pass_bot': False, 'filters': {'func': <function <lambda> at ...

> File "/Users/artem/Documents/PROGRAMMING/My/telebot/telebot_movie/handlers/custom_handlers/popular.py", line 25, in callback_serial_handler
    serial_info = popular_serials.populars()
                  │               └ <function populars at 0x1030854e0>
                  └ <module 'api.popular_serials' from '/Users/artem/Documents/PROGRAMMING/My/telebot/telebot_movie/api/popular_serials.py'>

  File "/Users/artem/Documents/PROGRAMMING/My/telebot/telebot_movie/api/popular_serials.py", line 55, in populars
    return message_text

UnboundLocalError: cannot access local variable 'message_text' where it is not associated with a value
